Workbook

Sheet Dashboard
A1: RENEWABLE ENERGY CONSOLIDATION MODEL
A2: Dashboard & Control Panel
A3: Report Generated: | B3: 2026-03-17 11:10:09
A5: REPORTING PERIOD SETTINGS
A7: Current Period: | B7: Jan-2024 | C7: [Use dropdown from Period_Control]
A8: Comparison Period: | B8: Dec-2023 | C8: [Use dropdown from Period_Control]
A9: Display Mode: | B9: Monthly | C9: [Monthly/Quarterly/Annual]
A10: Reporting Currency: | B10: INR
A12: Validation Status: | B12: =Validation!G2 | C12: =IF(B12=0,"ALL CHECKS PASSED","ISSUES DETECTED")
A14: Metric | B14: Current | C14: Previous | D14: Change | E14: Change %
A15: Total Revenue | B15: =IFERROR(INDEX(Output_BS!$B$1:$B$1000,MATCH("Total Assets",Output_BS!$A$1:$A$1000,0)),0) | C15: =IFERROR(INDEX(Output_BS!$C$1:$C$1000,MATCH("Total Assets",Output_BS!$A$1:$A$1000,0)),0) | D15: =IFERROR(C15-B15,0) | E15: =IFERROR(IF(B15<>0,D15/B15,0),0)
A16: EBITDA | B16: =IFERROR(INDEX(Output_PL!$B$1:$B$1000,MATCH("Total Revenue",Output_PL!$A$1:$A$1000,0)),0) | C16: =IFERROR(INDEX(Output_PL!$C$1:$C$1000,MATCH("Total Revenue",Output_PL!$A$1:$A$1000,0)),0) | D16: =IFERROR(C16-B16,0) | E16: =IFERROR(IF(B16<>0,D16/B16,0),0)
A17: Profit before Tax | B17: =IFERROR(INDEX(Output_PL!$B$1:$B$1000,MATCH("EBITDA",Output_PL!$A$1:$A$1000,0)),0) | C17: =IFERROR(INDEX(Output_PL!$C$1:$C$1000,MATCH("EBITDA",Output_PL!$A$1:$A$1000,0)),0) | D17: =IFERROR(C17-B17,0) | E17: =IFERROR(IF(B17<>0,D17/B17,0),0)
A18: Profit after Tax | B18: =IFERROR(INDEX(Output_PL!$B$1:$B$1000,MATCH("Profit for the Year",Output_PL!$A$1:$A$1000,0)),0) | C18: =IFERROR(INDEX(Output_PL!$C$1:$C$1000,MATCH("Profit for the Year",Output_PL!$A$1:$A$1000,0)),0) | D18: =IFERROR(C18-B18,0) | E18: =IFERROR(IF(B18<>0,D18/B18,0),0)
A19: Total Assets | B19: =IFERROR(INDEX(Output_CF!$B$1:$B$1000,MATCH("Net Cash from Operating Activities",Output_CF!$A$1:$A$1000,0)),0) | C19: =IFERROR(INDEX(Output_CF!$C$1:$C$1000,MATCH("Net Cash from Operating Activities",Output_CF!$A$1:$A$1000,0)),0) | D19: =IFERROR(C19-B19,0) | E19: =IFERROR(IF(B19<>0,D19/B19,0),0)
A20: Total Equity | B20: =IFERROR(INDEX(Output_BS!$B$1:$B$1000,MATCH("Total Equity",Output_BS!$A$1:$A$1000,0)),0) | C20: =IFERROR(INDEX(Output_BS!$C$1:$C$1000,MATCH("Total Equity",Output_BS!$A$1:$A$1000,0)),0) | D20: =IFERROR(C20-B20,0) | E20: =IFERROR(IF(B20<>0,D20/B20,0),0)
A21: Net Debt
A23: NAVIGATION
A25: Go to Entity Master
A26: Go to Asset Master
A27: Go to TB Input
A28: Go to Balance Sheet
A29: Go to P&L Statement
A30: Go to Cash Flow
A31: Go to Validation
A33: VALIDATION STATUS
A35: Validation Checks Failed: | B35: 0 | C35: [All checks passed]

Sheet Entity_Master
A1: Entity_ID | B1: Entity_Name | C1: Entity_Type | D1: Parent_Entity_ID | E1: Ownership_% | F1: Effective_Ownership_% | G1: Consolidation_Method | H1: Principal_Activity | I1: Incorporation_Date | J1: Active_Status | K1: Reporting_Currency | L1: Primary_Segment | M1: Notes
A2: E001 | B2: Parent Renewable Ltd | C2: Parent | D2: - | E2: 1 | F2: 1 | G2: Full | H2: EPC & Power Generation | I2: 40179 | J2: Active | K2: INR | L2: EPC
A3: E002 | B3: Solar SPV 1 Ltd | C3: SPV | D3: E001 | E3: 1 | F3: 1 | G3: Full | H3: Solar Power Generation | I3: 43922 | J3: Active | K3: INR | L3: Power Generation | M3: 100% owned
A4: E003 | B4: Solar SPV 2 Ltd | C4: SPV | D4: E001 | E4: 0.6 | F4: 0.6 | G4: Full | H4: Solar Power Generation | I4: 44757 | J4: Active | K4: INR | L4: Power Generation | M4: 60% owned, 40% NCI
A5: E004 | B5: Wind JV Pvt Ltd | C5: JV | D5: E001 | E5: 0.5 | F5: 0.5 | G5: Equity | H5: Wind Power Generation | I5: 44256 | J5: Active | K5: INR | L5: Power Generation | M5: Joint Venture
A6: E005 | B6: Biogas Associate Ltd | C6: Associate | D6: E001 | E6: 0.26 | F6: 0.26 | G6: Equity | H6: Biogas Power Generation | I6: 43709 | J6: Active | K6: INR | L6: Power Generation | M6: Associate company

Sheet Asset_Master
A1: Asset_ID | B1: Asset_Name | C1: Entity_ID | D1: Category | E1: Type | F1: Sub_Type | G1: Capacity_MW | H1: Capacity_Unit | I1: Location | J1: COD_Date | K1: Asset_Status | L1: Customer_Type | M1: PPA_Rate | N1: PPA_Term_Years | O1: Estimated_Cost_Cr | P1: Debt_Equity_Ratio | Q1: Notes
A2: A001 | B2: Mumbai Rooftop Solar Project | C2: E002 | D2: Solar | E2: Rooftop | F2: C&I | G2: 10 | H2: MW | I2: Maharashtra, Mumbai | J2: 44362 | K2: Operational | L2: C&I | M2: 4.5 | N2: 25 | O2: 60 | P2: 70:30 | Q2: Commissioned June 2021
A3: A002 | B3: Gujarat Utility Solar Plant | C3: E003 | D3: Solar | E3: Utility Scale | F3: PSU Direct | G3: 50 | H3: MW | I3: Gujarat, Kutch | J3: 44986 | K3: Operational | L3: PSU | M3: 2.8 | N3: 25 | O3: 250 | P3: 75:25 | Q3: Feed-in to state grid
A4: A003 | B4: Pune BESS Project | C4: E002 | D4: BESS | E4: Standalone | F4: - | G4: 10 | H4: MWh | I4: Maharashtra, Pune | K4: CWIP | L4: C&I | M4: 0 | N4: 10 | O4: 80 | P4: 60:40 | Q4: Under construction
A5: A004 | B5: CBG Plant - Sangli | C5: E005 | D5: Biogas | E5: CBG Plants | F5: - | G5: 5 | H5: TPD | I5: Maharashtra, Sangli | J5: 44136 | K5: Operational | L5: Merchant | M5: 0 | N5: 0 | O5: 15 | P5: 50:50 | Q5: Compressed biogas production

Sheet Reference_Lists
A1: Entity_Types | B1: Asset_Category | C1: Solar_Type | D1: Rooftop_SubType | E1: UtilityScale_SubType | F1: Biogas_Type | G1: BESS_Type | H1: Asset_Status | I1: Customer_Type | J1: Active_Status | K1: Currency_List | L1: Consolidation_Method | M1: Business_Segment | N1: Period_Month | O1: Period_Quarter | P1: Period_Year
A2: Parent | B2: Solar | C2: Rooftop | D2: C&I | E2: C&I | F2: CBG Plants | G2: Standalone | H2: CWIP | I2: Discom | J2: Active | K2: INR | L2: Full | M2: EPC | N2: Jan-2024 | O2: Q1-FY24 | P2: FY2024
A3: SPV | B3: Biogas | C3: Utility Scale | D3: Residential | E3: Govt/PSU Direct | F3: Portable Units | G3: Solar + BESS | H3: Operational | I3: PSU | J3: Inactive | K3: USD | L3: Equity | M3: Power Generation | N3: Feb-2024 | O3: Q2-FY24 | P3: FY2025
A4: JV | B4: BESS | C4: Floating Solar | D4: Govt/PSU | E4: Subcontract | F4: Gas Upgradation | G4: Others | H4: Disposed | I4: C&I | J4: Disposed | K4: EUR | L4: None | M4: O&M Services | N4: Mar-2024 | O4: Q3-FY24
A5: Associate | B5: Hybrid | C5: Solar Water Pumping | D5: Others | E5: Merchant | F5: Rehab Plants | I5: Captive | M5: Product Sales | N5: Apr-2024 | O5: Q4-FY24
B6: Wind | C6: Others | E6: Others | F6: Others | I6: Merchant | M6: Others | N6: May-2024
B7: Others | N7: Jun-2024
N8: Jul-2024
N9: Aug-2024
N10: Sep-2024
N11: Oct-2024
N12: Nov-2024
N13: Dec-2024

Sheet Mapping_BS
A1: FS_Line_Code | B1: FS_Line_Name | C1: FS_Section | D1: FS_Sub_Section | E1: Display_Order | F1: Indent_Level | G1: Account_Pattern | H1: Account_Nature | I1: Rollup_Parent | J1: Include_in_Total | K1: Bold_Format | L1: Notes
A2: BS_A_000 | B2: TOTAL ASSETS | C2: Assets | D2: Total | E2: 1000 | F2: 0 | H2: Debit | J2: Yes | K2: Yes | L2: Top level total
A3: BS_A_100 | B3: Non-Current Assets | C3: Assets | D3: Non-Current | E3: 100 | F3: 1 | H3: Debit | I3: BS_A_000 | J3: Yes | K3: Yes | L3: Sub-total
A4: BS_A_110 | B4: Property, Plant & Equipment | C4: Assets | D4: Non-Current | E4: 110 | F4: 2 | G4: 110* | H4: Debit | I4: BS_A_100 | J4: Yes | K4: No | L4: PPE net block
A5: BS_A_120 | B5: Capital Work-in-Progress | C5: Assets | D5: Non-Current | E5: 120 | F5: 2 | G5: 111* | H5: Debit | I5: BS_A_100 | J5: Yes | K5: No | L5: CWIP
A6: BS_A_130 | B6: Right-of-use Assets | C6: Assets | D6: Non-Current | E6: 130 | F6: 2 | G6: 112* | H6: Debit | I6: BS_A_100 | J6: Yes | K6: No | L6: Lease assets
A7: BS_A_140 | B7: Intangible Assets | C7: Assets | D7: Non-Current | E7: 140 | F7: 2 | G7: 113* | H7: Debit | I7: BS_A_100 | J7: Yes | K7: No | L7: Intangibles
A8: BS_A_150 | B8: Financial Assets (Non-Current) | C8: Assets | D8: Non-Current | E8: 150 | F8: 2 | H8: Debit | I8: BS_A_100 | J8: Yes | K8: Yes | L8: Sub-header
A9: BS_A_151 | B9: - Investments in JV/Associates | C9: Assets | D9: Non-Current | E9: 151 | F9: 3 | G9: 120* | H9: Debit | I9: BS_A_150 | J9: Yes | K9: No | L9: Equity method
A10: BS_A_152 | B10: - Other Investments | C10: Assets | D10: Non-Current | E10: 152 | F10: 3 | G10: 121* | H10: Debit | I10: BS_A_150 | J10: Yes | K10: No | L10: Financial investments
A11: BS_A_153 | B11: - Loans (Non-Current) | C11: Assets | D11: Non-Current | E11: 153 | F11: 3 | G11: 122* | H11: Debit | I11: BS_A_150 | J11: Yes | K11: No | L11: Long-term loans
A12: BS_A_200 | B12: Current Assets | C12: Assets | D12: Current | E12: 200 | F12: 1 | H12: Debit | I12: BS_A_000 | J12: Yes | K12: Yes | L12: Sub-total
A13: BS_A_210 | B13: Inventories | C13: Assets | D13: Current | E13: 210 | F13: 2 | G13: 140* | H13: Debit | I13: BS_A_200 | J13: Yes | K13: No | L13: Materials inventory
A14: BS_A_220 | B14: Financial Assets (Current) | C14: Assets | D14: Current | E14: 220 | F14: 2 | H14: Debit | I14: BS_A_200 | J14: Yes | K14: Yes | L14: Sub-header
A15: BS_A_221 | B15: - Trade Receivables | C15: Assets | D15: Current | E15: 221 | F15: 3 | G15: 141* | H15: Debit | I15: BS_A_220 | J15: Yes | K15: No | L15: From customers
A16: BS_A_222 | B16: - Cash and Cash Equivalents | C16: Assets | D16: Current | E16: 222 | F16: 3 | G16: 142* | H16: Debit | I16: BS_A_220 | J16: Yes | K16: No | L16: Cash balances
A17: BS_E_000 | B17: TOTAL EQUITY & LIABILITIES | C17: Equity | D17: Total | E17: 2000 | F17: 0 | H17: Credit | J17: Yes | K17: Yes | L17: Top level total
A18: BS_E_100 | B18: Equity | C18: Equity | D18: Equity | E18: 2100 | F18: 1 | H18: Credit | I18: BS_E_000 | J18: Yes | K18: Yes | L18: Sub-total
A19: BS_E_110 | B19: Equity Share Capital | C19: Equity | D19: Equity | E19: 2110 | F19: 2 | G19: 200* | H19: Credit | I19: BS_E_100 | J19: Yes | K19: No | L19: Share capital
A20: BS_E_120 | B20: Other Equity | C20: Equity | D20: Equity | E20: 2120 | F20: 2 | G20: 210*,220*,230* | H20: Credit | I20: BS_E_100 | J20: Yes | K20: No | L20: Reserves & surplus
A21: BS_E_130 | B21: Non-Controlling Interests | C21: Equity | D21: Equity | E21: 2130 | F21: 2 | G21: [Calculated] | H21: Credit | I21: BS_E_100 | J21: Yes | K21: No | L21: Minority interest
A22: BS_L_100 | B22: Non-Current Liabilities | C22: Liabilities | D22: Non-Current | E22: 2200 | F22: 1 | H22: Credit | I22: BS_E_000 | J22: Yes | K22: Yes | L22: Sub-total
A23: BS_L_110 | B23: Financial Liabilities (NC) | C23: Liabilities | D23: Non-Current | E23: 2210 | F23: 2 | H23: Credit | I23: BS_L_100 | J23: Yes | K23: Yes | L23: Sub-header
A24: BS_L_111 | B24: - Borrowings (Non-Current) | C24: Liabilities | D24: Non-Current | E24: 2211 | F24: 3 | G24: 300* | H24: Credit | I24: BS_L_110 | J24: Yes | K24: No | L24: Long-term debt
A25: BS_L_200 | B25: Current Liabilities | C25: Liabilities | D25: Current | E25: 2300 | F25: 1 | H25: Credit | I25: BS_E_000 | J25: Yes | K25: Yes | L25: Sub-total
A26: BS_L_210 | B26: Financial Liabilities (Current) | C26: Liabilities | D26: Current | E26: 2310 | F26: 2 | H26: Credit | I26: BS_L_200 | J26: Yes | K26: Yes | L26: Sub-header
A27: BS_L_211 | B27: - Borrowings (Current) | C27: Liabilities | D27: Current | E27: 2311 | F27: 3 | G27: 400* | H27: Credit | I27: BS_L_210 | J27: Yes | K27: No | L27: Short-term debt
A28: BS_L_213 | B28: - Trade Payables | C28: Liabilities | D28: Current | E28: 2313 | F28: 3 | G28: 402* | H28: Credit | I28: BS_L_210 | J28: Yes | K28: No | L28: Vendor payables

Sheet Mapping_PL
A1: FS_Line_Code | B1: FS_Line_Name | C1: FS_Section | D1: FS_Sub_Section | E1: Display_Order | F1: Indent_Level | G1: Account_Pattern | H1: Account_Nature | I1: Rollup_Parent | J1: Segment_Applicable
A2: PL_I_000 | B2: TOTAL INCOME | C2: Income | D2: Total | E2: 1000 | F2: 0 | H2: Credit | J2: No
A3: PL_I_100 | B3: Revenue from Operations | C3: Income | D3: Operating | E3: 100 | F3: 1 | H3: Credit | I3: PL_I_000 | J3: Yes
A4: PL_I_110 | B4: Sale of Power - Solar | C4: Income | D4: Operating | E4: 110 | F4: 2 | G4: 500* | H4: Credit | I4: PL_I_100 | J4: Yes
A5: PL_I_120 | B5: Sale of Power - Biogas | C5: Income | D5: Operating | E5: 120 | F5: 2 | G5: 501* | H5: Credit | I5: PL_I_100 | J5: Yes
A6: PL_I_140 | B6: EPC Revenue | C6: Income | D6: Operating | E6: 140 | F6: 2 | G6: 510* | H6: Credit | I6: PL_I_100 | J6: Yes
A7: PL_I_150 | B7: O&M Services Revenue | C7: Income | D7: Operating | E7: 150 | F7: 2 | G7: 520* | H7: Credit | I7: PL_I_100 | J7: Yes
A8: PL_I_170 | B8: Other Operating Revenue | C8: Income | D8: Operating | E8: 170 | F8: 2 | G8: 540* | H8: Credit | I8: PL_I_100 | J8: Yes
A9: PL_I_200 | B9: Other Income | C9: Income | D9: Non-Operating | E9: 200 | F9: 1 | H9: Credit | I9: PL_I_000 | J9: No
A10: PL_I_210 | B10: Interest Income | C10: Income | D10: Non-Operating | E10: 210 | F10: 2 | G10: 550* | H10: Credit | I10: PL_I_200 | J10: No
A11: PL_I_220 | B11: Dividend Income | C11: Income | D11: Non-Operating | E11: 220 | F11: 2 | G11: 551* | H11: Credit | I11: PL_I_200 | J11: No
A12: PL_E_000 | B12: TOTAL EXPENSES | C12: Expenses | D12: Total | E12: 2000 | F12: 0 | H12: Debit | J12: No
A13: PL_E_100 | B13: Cost of Power / Fuel | C13: Expenses | D13: Operating | E13: 2100 | F13: 1 | G13: 600* | H13: Debit | I13: PL_E_000 | J13: Yes
A14: PL_E_110 | B14: Cost of Materials (EPC) | C14: Expenses | D14: Operating | E14: 2110 | F14: 1 | G14: 610* | H14: Debit | I14: PL_E_000 | J14: Yes
A15: PL_E_120 | B15: Subcontracting Charges | C15: Expenses | D15: Operating | E15: 2120 | F15: 1 | G15: 620* | H15: Debit | I15: PL_E_000 | J15: Yes
A16: PL_E_130 | B16: Employee Benefits Expense | C16: Expenses | D16: Operating | E16: 2130 | F16: 1 | G16: 630* | H16: Debit | I16: PL_E_000 | J16: Yes
A17: PL_E_140 | B17: Finance Costs | C17: Expenses | D17: Operating | E17: 2140 | F17: 1 | G17: 640* | H17: Debit | I17: PL_E_000 | J17: No
A18: PL_E_150 | B18: Depreciation & Amortization | C18: Expenses | D18: Operating | E18: 2150 | F18: 1 | G18: 650* | H18: Debit | I18: PL_E_000 | J18: No
A19: PL_E_160 | B19: O&M Expenses | C19: Expenses | D19: Operating | E19: 2160 | F19: 1 | G19: 660* | H19: Debit | I19: PL_E_000 | J19: Yes
A20: PL_E_170 | B20: Other Expenses | C20: Expenses | D20: Operating | E20: 2170 | F20: 1 | G20: 670* | H20: Debit | I20: PL_E_000 | J20: Yes
A21: PL_R_100 | B21: Profit before Tax | C21: Result | D21: Result | E21: 3100 | F21: 1 | G21: [Calculated] | J21: No
A22: PL_R_110 | B22: Tax Expense - Current | C22: Expenses | D22: Tax | E22: 3110 | F22: 2 | G22: 700* | H22: Debit | J22: No
A23: PL_R_120 | B23: Tax Expense - Deferred | C23: Expenses | D23: Tax | E23: 3120 | F23: 2 | G23: 701* | H23: Debit | J23: No
A24: PL_R_200 | B24: Profit for the Year | C24: Result | D24: Result | E24: 3200 | F24: 1 | G24: [Calculated] | J24: No
A25: PL_R_300 | B25: Attributable to Owners | C25: Result | D25: Attribution | E25: 3300 | F25: 2 | G25: [Calculated] | J25: No
A26: PL_R_310 | B26: Attributable to NCI | C26: Result | D26: Attribution | E26: 3310 | F26: 2 | G26: [Calculated] | J26: No

Sheet Mapping_CF
A1: CF_Line_Code | B1: CF_Line_Name | C1: CF_Section | D1: Display_Order | E1: Indent_Level | F1: Source_Type | G1: Source_Reference | H1: Add_Subtract
A2: CF_O_000 | B2: A. CASH FLOW FROM OPERATING ACTIVITIES | C2: Operating | D2: 1000 | E2: 0 | F2: Section
A3: CF_O_010 | B3: Profit before Tax | C3: Operating | D3: 1010 | E3: 1 | F3: PL_Link | G3: PL_R_100 | H3: Add
A4: CF_O_020 | B4: Adjustments: | C4: Operating | D4: 1020 | E4: 1 | F4: Header
A5: CF_O_021 | B5: Depreciation & Amortization | C5: Operating | D5: 1021 | E5: 2 | F5: PL_Link | G5: PL_E_150 | H5: Add
A6: CF_O_022 | B6: Finance Costs | C6: Operating | D6: 1022 | E6: 2 | F6: PL_Link | G6: PL_E_140 | H6: Add
A7: CF_O_023 | B7: Interest Income | C7: Operating | D7: 1023 | E7: 2 | F7: PL_Link | G7: PL_I_210 | H7: Subtract
A8: CF_O_030 | B8: Operating Profit before WC changes | C8: Operating | D8: 1030 | E8: 1 | F8: Calculated | G8: Sum_Above | H8: Add
A9: CF_O_040 | B9: Working Capital changes: | C9: Operating | D9: 1040 | E9: 1 | F9: Header
A10: CF_O_041 | B10: (Increase)/Decrease in Receivables | C10: Operating | D10: 1041 | E10: 2 | F10: BS_Movement | G10: BS_A_221 | H10: Subtract
A11: CF_O_042 | B11: Increase/(Decrease) in Payables | C11: Operating | D11: 1042 | E11: 2 | F11: BS_Movement | G11: BS_L_213 | H11: Add
A12: CF_O_050 | B12: Cash Generated from Operations | C12: Operating | D12: 1050 | E12: 1 | F12: Calculated | G12: Sum_Above | H12: Add
A13: CF_O_060 | B13: Income Tax Paid | C13: Operating | D13: 1060 | E13: 1 | F13: PL_Link | G13: PL_R_110 | H13: Subtract
A14: CF_O_100 | B14: Net Cash from Operating Activities (A) | C14: Operating | D14: 1100 | E14: 1 | F14: Calculated | G14: Sum_Section | H14: Add
A15: CF_I_000 | B15: B. CASH FLOW FROM INVESTING ACTIVITIES | C15: Investing | D15: 2000 | E15: 0 | F15: Section
A16: CF_I_010 | B16: Purchase of PPE | C16: Investing | D16: 2010 | E16: 1 | F16: BS_Movement | G16: BS_A_110 | H16: Subtract
A17: CF_I_020 | B17: Interest Received | C17: Investing | D17: 2020 | E17: 1 | F17: PL_Link | G17: PL_I_210 | H17: Add
A18: CF_I_100 | B18: Net Cash from Investing Activities (B) | C18: Investing | D18: 2100 | E18: 1 | F18: Calculated | G18: Sum_Section | H18: Add
A19: CF_F_000 | B19: C. CASH FLOW FROM FINANCING ACTIVITIES | C19: Financing | D19: 3000 | E19: 0 | F19: Section
A20: CF_F_010 | B20: Proceeds from Borrowings | C20: Financing | D20: 3010 | E20: 1 | F20: BS_Movement | G20: BS_L_111 | H20: Add
A21: CF_F_020 | B21: Interest Paid | C21: Financing | D21: 3020 | E21: 1 | F21: PL_Link | G21: PL_E_140 | H21: Subtract
A22: CF_F_100 | B22: Net Cash from Financing Activities (C) | C22: Financing | D22: 3100 | E22: 1 | F22: Calculated | G22: Sum_Section | H22: Add
A23: CF_S_000 | B23: SUMMARY | C23: Summary | D23: 4000 | E23: 0 | F23: Section
A24: CF_S_010 | B24: Net Increase/(Decrease) in Cash (A+B+C) | C24: Summary | D24: 4010 | E24: 1 | F24: Calculated | G24: Sum_ABC | H24: Add
A25: CF_S_020 | B25: Cash at Beginning of Period | C25: Summary | D25: 4020 | E25: 1 | F25: BS_Opening | G25: BS_A_222 | H25: Add
A26: CF_S_030 | B26: Cash at End of Period | C26: Summary | D26: 4030 | E26: 1 | F26: Calculated | G26: Sum_Change | H26: Add

Sheet TB_Input
A1: TRIAL BALANCE INPUT | N1: Account_Prefix
E2: E001 - Parent Renewable Ltd | H2: E002 - Solar SPV 1 Ltd | K2: E003 - Solar SPV 2 Ltd
E3: Jan-2024 | H3: Jan-2024 | K3: Jan-2024
A4: Account_Code | B4: Account_Name | C4: FS_Category | D4: Account_Nature | E4: Dr | F4: Cr | G4: Net | H4: Dr | I4: Cr | J4: Net | K4: Dr | L4: Cr | M4: Net
A5: 100001 | B5: Cash in Hand | C5: BS | D5: Debit | E5: 600 | F5: 0 | G5: =IF($D5="Debit",E5-F5,F5-E5) | H5: 100 | I5: 0 | J5: =IF($D5="Debit",H5-I5,I5-H5) | K5: 50 | L5: 0 | M5: =IF($D5="Debit",K5-L5,L5-K5) | N5: =LEFT(A5,3)
A6: 110001 | B6: PPE - Solar Plants | C6: BS | D6: Debit | E6: 11000 | F6: 1000 | G6: =IF($D6="Debit",E6-F6,F6-E6) | H6: 50000 | I6: 5000 | J6: =IF($D6="Debit",H6-I6,I6-H6) | K6: 25000 | L6: 2500 | M6: =IF($D6="Debit",K6-L6,L6-K6) | N6: =LEFT(A6,3)
A7: 111001 | B7: CWIP - Solar Projects | C7: BS | D7: Debit | E7: 2000 | F7: 0 | G7: =IF($D7="Debit",E7-F7,F7-E7) | H7: 30000 | I7: 0 | J7: =IF($D7="Debit",H7-I7,I7-H7) | K7: 10000 | L7: 0 | M7: =IF($D7="Debit",K7-L7,L7-K7) | N7: =LEFT(A7,3)
A8: 122001 | B8: Loan to SPV | C8: BS | D8: Debit | E8: 20000 | F8: 0 | G8: =IF($D8="Debit",E8-F8,F8-E8) | H8: 0 | I8: 0 | J8: =IF($D8="Debit",H8-I8,I8-H8) | K8: 0 | L8: 0 | M8: =IF($D8="Debit",K8-L8,L8-K8) | N8: =LEFT(A8,3)
A9: 141001 | B9: Trade Receivables | C9: BS | D9: Debit | E9: 5000 | F9: 0 | G9: =IF($D9="Debit",E9-F9,F9-E9) | H9: 8000 | I9: 0 | J9: =IF($D9="Debit",H9-I9,I9-H9) | K9: 3000 | L9: 0 | M9: =IF($D9="Debit",K9-L9,L9-K9) | N9: =LEFT(A9,3)
A10: 142001 | B10: Cash at Bank | C10: BS | D10: Debit | E10: 15000 | F10: 0 | G10: =IF($D10="Debit",E10-F10,F10-E10) | H10: 2000 | I10: 0 | J10: =IF($D10="Debit",H10-I10,I10-H10) | K10: 1000 | L10: 0 | M10: =IF($D10="Debit",K10-L10,L10-K10) | N10: =LEFT(A10,3)
A11: 200001 | B11: Equity Share Capital | C11: BS | D11: Credit | E11: 0 | F11: 50000 | G11: =IF($D11="Debit",E11-F11,F11-E11) | H11: 0 | I11: 30000 | J11: =IF($D11="Debit",H11-I11,I11-H11) | K11: 0 | L11: 15000 | M11: =IF($D11="Debit",K11-L11,L11-K11) | N11: =LEFT(A11,3)
A12: 210001 | B12: Retained Earnings | C12: BS | D12: Credit | E12: 0 | F12: 5000 | G12: =IF($D12="Debit",E12-F12,F12-E12) | H12: 0 | I12: 2000 | J12: =IF($D12="Debit",H12-I12,I12-H12) | K12: 0 | L12: 1000 | M12: =IF($D12="Debit",K12-L12,L12-K12) | N12: =LEFT(A12,3)
A13: 300001 | B13: Term Loans | C13: BS | D13: Credit | E13: 0 | F13: 0 | G13: =IF($D13="Debit",E13-F13,F13-E13) | H13: 0 | I13: 30000 | J13: =IF($D13="Debit",H13-I13,I13-H13) | K13: 0 | L13: 15000 | M13: =IF($D13="Debit",K13-L13,L13-K13) | N13: =LEFT(A13,3)
A14: 302001 | B14: Loan from Parent | C14: BS | D14: Credit | E14: 0 | F14: 0 | G14: =IF($D14="Debit",E14-F14,F14-E14) | H14: 0 | I14: 20000 | J14: =IF($D14="Debit",H14-I14,I14-H14) | K14: 0 | L14: 0 | M14: =IF($D14="Debit",K14-L14,L14-K14) | N14: =LEFT(A14,3)
A15: 402001 | B15: Trade Payables | C15: BS | D15: Credit | E15: 0 | F15: 2500 | G15: =IF($D15="Debit",E15-F15,F15-E15) | H15: 0 | I15: 5000 | J15: =IF($D15="Debit",H15-I15,I15-H15) | K15: 0 | L15: 2500 | M15: =IF($D15="Debit",K15-L15,L15-K15) | N15: =LEFT(A15,3)
A16: 500001 | B16: Power Sales - Solar | C16: PL | D16: Credit | E16: 0 | F16: 0 | G16: =IF($D16="Debit",E16-F16,F16-E16) | H16: 0 | I16: 10000 | J16: =IF($D16="Debit",H16-I16,I16-H16) | K16: 0 | L16: 5000 | M16: =IF($D16="Debit",K16-L16,L16-K16) | N16: =LEFT(A16,3)
... A22: 660001 | B22: O&M Expenses | C22: PL | D22: Debit | E22: 0 | F22: 0 | G22: =IF($D22="Debit",E22-F22,F22-E22) | H22: 1000 | I22: 0 | J22: =IF($D22="Debit",H22-I22,I22-H22) | K22: 500 | L22: 0 | M22: =IF($D22="Debit",K22-L22,L22-K22) | N22: =LEFT(A22,3)
A23: TOTAL | E23: 79600 | F23: 88500 | G23: =IF($D23="Debit",E23-F23,F23-E23) | H23: 98600 | I23: 102000 | J23: =IF($D23="Debit",H23-I23,I23-H23) | K23: 43350 | L23: 41000 | M23: =IF($D23="Debit",K23-L23,L23-K23) | N23: =LEFT(A23,3)
A24: 115999 | B24: TEST - New PPE Account | C24: BS | D24: Debit | E24: 1000 | F24: 0 | G24: =IF($D24="Debit",E24-F24,F24-E24) | J24: =IF($D24="Debit",H24-I24,I24-H24) | M24: =IF($D24="Debit",K24-L24,L24-K24)
A25: 510005 | B25: Test Revenue | D25: Credit | E25: 500 | F25: 0 | H25: 600 | I25: 0 | K25: 700 | L25: 0
A201: 610001 | B201: Test Expense Beyond Boundary | D201: Debit | E201: 5000 | F201: 0

Sheet IC_Transactions
A1: IC_Trans_ID | B1: Transaction_Type | C1: From_Entity_ID | D1: To_Entity_ID | E1: Description | F1: Amount | G1: Profit_% | H1: Profit_Amount | I1: Period | J1: FS_Impact_From | K1: FS_Impact_To | L1: Elimination_Status | M1: Notes
A2: IC001 | B2: EPC_Revenue | C2: E001 | D2: E002 | E2: Solar plant construction for SPV1 | F2: 30000 | G2: 0.1 | H2: =IF(B2="EPC_Revenue", F2*G2, 0) | I2: Jan-2024 | J2: EPC Revenue | K2: CWIP | L2: Pending | M2: To be eliminated
A3: IC002 | B3: Loan_Given | C3: E001 | D3: E002 | E3: Project financing loan to SPV1 | F3: 20000 | G3: 0 | H3: =IF(B3="EPC_Revenue", F3*G3, 0) | I3: Jan-2024 | J3: Loan Asset | K3: Loan Liability | L3: Pending | M3: To be eliminated
A4: IC003 | B4: Interest_Charged | C4: E001 | D4: E002 | E4: Interest on loan @12% p.a. | F4: 200 | G4: 0 | H4: =IF(B4="EPC_Revenue", F4*G4, 0) | I4: Jan-2024 | J4: Interest Income | K4: Finance Cost | L4: Pending | M4: To be eliminated

Sheet Consolidation_BS
A1: FS_Line_Code | B1: FS_Line_Name | C1: Display_Order | D1: Indent_Level | E1: E001_Jan24 | F1: E002_Jan24 | G1: E003_Jan24 | H1: Pre_Elim_Total_Jan24 | I1: Eliminations_Jan24 | J1: Post_Elim_Total_Jan24
A2: BS_A_000 | B2: TOTAL ASSETS | C2: 1000 | D2: 0 | E2: =E3+E12 | F2: =F3+F12 | G2: =G3+G12 | H2: 137500 | I2: =IFERROR(SUMIF(Eliminations!$B$1:$B$1000,A2,Eliminations!$E$1:$E$1000),0)-IFERROR(SUMIF(Eliminations!$C$1:$C$1000,A2,Eliminations!$E$1:$E$1000),0) | J2: 137500
A3: BS_A_100 | B3: Non-Current Assets | C3: 100 | D3: 1 | E3: =E4+E5+E6+E7+E8+E9+E10+E11 | F3: =F4+F5+F6+F7+F8+F9+F10+F11 | G3: =G4+G5+G6+G7+G8+G9+G10+G11 | H3: 119500 | I3: =IFERROR(SUMIF(Eliminations!$B$1:$B$1000,A3,Eliminations!$E$1:$E$1000),0)-IFERROR(SUMIF(Eliminations!$C$1:$C$1000,A3,Eliminations!$E$1:$E$1000),0) | J3: 119500
A4: BS_A_110 | B4: Property, Plant & Equipment | C4: 110 | D4: 2 | E4: =SUMPRODUCT((LEFT(TB_Input!$A$5:$A$200,3)="110")*(TB_Input!$G$5:$G$200)) | F4: =SUMPRODUCT((LEFT(TB_Input!$A$5:$A$200,3)="110")*(TB_Input!$J$5:$J$200)) | G4: =SUMPRODUCT((LEFT(TB_Input!$A$5:$A$200,3)="110")*(TB_Input!$M$5:$M$200)) | H4: 77500 | I4: =IFERROR(SUMIF(Eliminations!$B$1:$B$1000,A4,Eliminations!$E$1:$E$1000),0)-IFERROR(SUMIF(Eliminations!$C$1:$C$1000,A4,Eliminations!$E$1:$E$1000),0) | J4: 77500
A5: BS_A_120 | B5: Capital Work-in-Progress | C5: 120 | D5: 2 | E5: =SUMPRODUCT((LEFT(TB_Input!$A$5:$A$200,3)="111")*(TB_Input!$G$5:$G$200)) | F5: =SUMPRODUCT((LEFT(TB_Input!$A$5:$A$200,3)="111")*(TB_Input!$J$5:$J$200)) | G5: =SUMPRODUCT((LEFT(TB_Input!$A$5:$A$200,3)="111")*(TB_Input!$M$5:$M$200)) | H5: 42000 | I5: =IFERROR(SUMIF(Eliminations!$B$1:$B$1000,A5,Eliminations!$E$1:$E$1000),0)-IFERROR(SUMIF(Eliminations!$C$1:$C$1000,A5,Eliminations!$E$1:$E$1000),0) | J5: 42000
A6: BS_A_130 | B6: Right-of-use Assets | C6: 130 | D6: 2 | E6: =SUMPRODUCT((LEFT(TB_Input!$A$5:$A$200,3)="112")*(TB_Input!$G$5:$G$200)) | F6: =SUMPRODUCT((LEFT(TB_Input!$A$5:$A$200,3)="112")*(TB_Input!$J$5:$J$200)) | G6: =SUMPRODUCT((LEFT(TB_Input!$A$5:$A$200,3)="112")*(TB_Input!$M$5:$M$200)) | H6: 0 | I6: =IFERROR(SUMIF(Eliminations!$B$1:$B$1000,A6,Eliminations!$E$1:$E$1000),0)-IFERROR(SUMIF(Eliminations!$C$1:$C$1000,A6,Eliminations!$E$1:$E$1000),0) | J6: 0
A7: BS_A_140 | B7: Intangible Assets | C7: 140 | D7: 2 | E7: =SUMPRODUCT((LEFT(TB_Input!$A$5:$A$200,3)="113")*(TB_Input!$G$5:$G$200)) | F7: =SUMPRODUCT((LEFT(TB_Input!$A$5:$A$200,3)="113")*(TB_Input!$J$5:$J$200)) | G7: =SUMPRODUCT((LEFT(TB_Input!$A$5:$A$200,3)="113")*(TB_Input!$M$5:$M$200)) | H7: 0 | I7: =IFERROR(SUMIF(Eliminations!$B$1:$B$1000,A7,Eliminations!$E$1:$E$1000),0)-IFERROR(SUMIF(Eliminations!$C$1:$C$1000,A7,Eliminations!$E$1:$E$1000),0) | J7: 0
A8: BS_A_150 | B8: Financial Assets (Non-Current) | C8: 150 | D8: 2 | E8: =E9+E10+E11 | F8: =F9+F10+F11 | G8: =G9+G10+G11 | H8: 0 | I8: =IFERROR(SUMIF(Eliminations!$B$1:$B$1000,A8,Eliminations!$E$1:$E$1000),0)-IFERROR(SUMIF(Eliminations!$C$1:$C$1000,A8,Eliminations!$E$1:$E$1000),0) | J8: 0
A9: BS_A_151 | B9: - Investments in JV/Associates | C9: 151 | D9: 3 | E9: =SUMPRODUCT((LEFT(TB_Input!$A$5:$A$200,3)="120")*(TB_Input!$G$5:$G$200)) | F9: =SUMPRODUCT((LEFT(TB_Input!$A$5:$A$200,3)="120")*(TB_Input!$J$5:$J$200)) | G9: =SUMPRODUCT((LEFT(TB_Input!$A$5:$A$200,3)="120")*(TB_Input!$M$5:$M$200)) | H9: 0 | I9: =IFERROR(SUMIF(Eliminations!$B$1:$B$1000,A9,Eliminations!$E$1:$E$1000),0)-IFERROR(SUMIF(Eliminations!$C$1:$C$1000,A9,Eliminations!$E$1:$E$1000),0) | J9: 0
A10: BS_A_152 | B10: - Other Investments | C10: 152 | D10: 3 | E10: =SUMPRODUCT((LEFT(TB_Input!$A$5:$A$200,3)="121")*(TB_Input!$G$5:$G$200)) | F10: =SUMPRODUCT((LEFT(TB_Input!$A$5:$A$200,3)="121")*(TB_Input!$J$5:$J$200)) | G10: =SUMPRODUCT((LEFT(TB_Input!$A$5:$A$200,3)="121")*(TB_Input!$M$5:$M$200)) | H10: 0 | I10: =IFERROR(SUMIF(Eliminations!$B$1:$B$1000,A10,Eliminations!$E$1:$E$1000),0)-IFERROR(SUMIF(Eliminations!$C$1:$C$1000,A10,Eliminations!$E$1:$E$1000),0) | J10: 0
A11: BS_A_153 | B11: - Loans (Non-Current) | C11: 153 | D11: 3 | E11: =SUMPRODUCT((LEFT(TB_Input!$A$5:$A$200,3)="122")*(TB_Input!$G$5:$G$200)) | F11: =SUMPRODUCT((LEFT(TB_Input!$A$5:$A$200,3)="122")*(TB_Input!$J$5:$J$200)) | G11: =SUMPRODUCT((LEFT(TB_Input!$A$5:$A$200,3)="122")*(TB_Input!$M$5:$M$200)) | H11: 20000 | I11: =IFERROR(SUMIF(Eliminations!$B$1:$B$1000,A11,Eliminations!$E$1:$E$1000),0)-IFERROR(SUMIF(Eliminations!$C$1:$C$1000,A11,Eliminations!$E$1:$E$1000),0) | J11: 20000
A12: BS_A_200 | B12: Current Assets | C12: 200 | D12: 1 | E12: =E13+E14+E15+E16 | F12: =F13+F14+F15+F16 | G12: =G13+G14+G15+G16 | H12: 18000 | I12: =IFERROR(SUMIF(Eliminations!$B$1:$B$1000,A12,Eliminations!$E$1:$E$1000),0)-IFERROR(SUMIF(Eliminations!$C$1:$C$1000,A12,Eliminations!$E$1:$E$1000),0) | J12: 18000
A13: BS_A_210 | B13: Inventories | C13: 210 | D13: 2 | E13: =SUMPRODUCT((LEFT(TB_Input!$A$5:$A$200,3)="130")*(TB_Input!$G$5:$G$200)) | F13: =SUMPRODUCT((LEFT(TB_Input!$A$5:$A$200,3)="130")*(TB_Input!$J$5:$J$200)) | G13: =SUMPRODUCT((LEFT(TB_Input!$A$5:$A$200,3)="130")*(TB_Input!$M$5:$M$200)) | H13: 0 | I13: =IFERROR(SUMIF(Eliminations!$B$1:$B$1000,A13,Eliminations!$E$1:$E$1000),0)-IFERROR(SUMIF(Eliminations!$C$1:$C$1000,A13,Eliminations!$E$1:$E$1000),0) | J13: 0
A14: BS_A_220 | B14: Financial Assets (Current) | C14: 220 | D14: 2 | E14: =E15+E16 | F14: =F15+F16 | G14: =G15+G16 | H14: 18000 | I14: =IFERROR(SUMIF(Eliminations!$B$1:$B$1000,A14,Eliminations!$E$1:$E$1000),0)-IFERROR(SUMIF(Eliminations!$C$1:$C$1000,A14,Eliminations!$E$1:$E$1000),0) | J14: 18000
A15: BS_A_221 | B15: - Trade Receivables | C15: 221 | D15: 3 | E15: =SUMPRODUCT((LEFT(TB_Input!$A$5:$A$200,3)="140")*(TB_Input!$G$5:$G$200)) | F15: =SUMPRODUCT((LEFT(TB_Input!$A$5:$A$200,3)="140")*(TB_Input!$J$5:$J$200)) | G15: =SUMPRODUCT((LEFT(TB_Input!$A$5:$A$200,3)="140")*(TB_Input!$M$5:$M$200)) | H15: 0 | I15: =IFERROR(SUMIF(Eliminations!$B$1:$B$1000,A15,Eliminations!$E$1:$E$1000),0)-IFERROR(SUMIF(Eliminations!$C$1:$C$1000,A15,Eliminations!$E$1:$E$1000),0) | J15: 0
A16: BS_A_222 | B16: - Cash and Cash Equivalents | C16: 222 | D16: 3 | E16: =SUMPRODUCT((LEFT(TB_Input!$A$5:$A$200,3)="142")*(TB_Input!$G$5:$G$200)) | F16: =SUMPRODUCT((LEFT(TB_Input!$A$5:$A$200,3)="142")*(TB_Input!$J$5:$J$200)) | G16: =SUMPRODUCT((LEFT(TB_Input!$A$5:$A$200,3)="142")*(TB_Input!$M$5:$M$200)) | H16: 0 | I16: =IFERROR(SUMIF(Eliminations!$B$1:$B$1000,A16,Eliminations!$E$1:$E$1000),0)-IFERROR(SUMIF(Eliminations!$C$1:$C$1000,A16,Eliminations!$E$1:$E$1000),0) | J16: 0
A17: BS_E_000 | B17: TOTAL EQUITY & LIABILITIES | C17: 2000 | D17: 0 | E17: =E18+E22+E25 | F17: =F18+F22+F25 | G17: =G18+G22+G25 | H17: 45000 | I17: =IFERROR(SUMIF(Eliminations!$B$1:$B$1000,A17,Eliminations!$E$1:$E$1000),0)-IFERROR(SUMIF(Eliminations!$C$1:$C$1000,A17,Eliminations!$E$1:$E$1000),0) | J17: 45000
A18: BS_E_100 | B18: Equity | C18: 2100 | D18: 1 | E18: =E19+E20+E21 | F18: =F19+F20+F21 | G18: =G19+G20+G21 | H18: 3000 | I18: =IFERROR(SUMIF(Eliminations!$B$1:$B$1000,A18,Eliminations!$E$1:$E$1000),0)-IFERROR(SUMIF(Eliminations!$C$1:$C$1000,A18,Eliminations!$E$1:$E$1000),0) | J18: 3000
A19: BS_E_110 | B19: Equity Share Capital | C19: 2110 | D19: 2 | E19: =SUMPRODUCT((LEFT(TB_Input!$A$5:$A$200,3)="200")*(TB_Input!$G$5:$G$200)) | F19: =SUMPRODUCT((LEFT(TB_Input!$A$5:$A$200,3)="200")*(TB_Input!$J$5:$J$200)) | G19: =SUMPRODUCT((LEFT(TB_Input!$A$5:$A$200,3)="200")*(TB_Input!$M$5:$M$200)) | H19: 0 | I19: =IFERROR(SUMIF(Eliminations!$B$1:$B$1000,A19,Eliminations!$E$1:$E$1000),0)-IFERROR(SUMIF(Eliminations!$C$1:$C$1000,A19,Eliminations!$E$1:$E$1000),0) | J19: 0
A20: BS_E_120 | B20: Other Equity | C20: 2120 | D20: 2 | E20: =SUMPRODUCT((LEFT(TB_Input!$A$5:$A$200,3)="210")*(TB_Input!$G$5:$G$200)) | F20: =SUMPRODUCT((LEFT(TB_Input!$A$5:$A$200,3)="210")*(TB_Input!$J$5:$J$200)) | G20: =SUMPRODUCT((LEFT(TB_Input!$A$5:$A$200,3)="210")*(TB_Input!$M$5:$M$200)) | H20: 0 | I20: =IFERROR(SUMIF(Eliminations!$B$1:$B$1000,A20,Eliminations!$E$1:$E$1000),0)-IFERROR(SUMIF(Eliminations!$C$1:$C$1000,A20,Eliminations!$E$1:$E$1000),0) | J20: 0
A21: BS_E_130 | B21: Non-Controlling Interests | C21: 2130 | D21: 2 | E21: =SUMPRODUCT((LEFT(TB_Input!$A$5:$A$200,3)="220")*(TB_Input!$G$5:$G$200)) | F21: =SUMPRODUCT((LEFT(TB_Input!$A$5:$A$200,3)="220")*(TB_Input!$J$5:$J$200)) | G21: =SUMPRODUCT((LEFT(TB_Input!$A$5:$A$200,3)="220")*(TB_Input!$M$5:$M$200)) | H21: 45000 | I21: =IFERROR(SUMIF(Eliminations!$B$1:$B$1000,A21,Eliminations!$E$1:$E$1000),0)-IFERROR(SUMIF(Eliminations!$C$1:$C$1000,A21,Eliminations!$E$1:$E$1000),0) | J21: 45000
A22: BS_L_100 | B22: Non-Current Liabilities | C22: 2200 | D22: 1 | E22: =E23+E24 | F22: =F23+F24 | G22: =G23+G24 | H22: 0 | I22: =IFERROR(SUMIF(Eliminations!$B$1:$B$1000,A22,Eliminations!$E$1:$E$1000),0)-IFERROR(SUMIF(Eliminations!$C$1:$C$1000,A22,Eliminations!$E$1:$E$1000),0) | J22: 0
A23: BS_L_110 | B23: Financial Liabilities (NC) | C23: 2210 | D23: 2 | E23: =E24 | F23: =F24 | G23: =G24 | H23: 0 | I23: =IFERROR(SUMIF(Eliminations!$B$1:$B$1000,A23,Eliminations!$E$1:$E$1000),0)-IFERROR(SUMIF(Eliminations!$C$1:$C$1000,A23,Eliminations!$E$1:$E$1000),0) | J23: 0
A24: BS_L_111 | B24: - Borrowings (Non-Current) | C24: 2211 | D24: 3 | E24: =SUMPRODUCT((LEFT(TB_Input!$A$5:$A$200,3)="300")*(TB_Input!$G$5:$G$200)) | F24: =SUMPRODUCT((LEFT(TB_Input!$A$5:$A$200,3)="300")*(TB_Input!$J$5:$J$200)) | G24: =SUMPRODUCT((LEFT(TB_Input!$A$5:$A$200,3)="300")*(TB_Input!$M$5:$M$200)) | H24: 7500 | I24: =IFERROR(SUMIF(Eliminations!$B$1:$B$1000,A24,Eliminations!$E$1:$E$1000),0)-IFERROR(SUMIF(Eliminations!$C$1:$C$1000,A24,Eliminations!$E$1:$E$1000),0) | J24: 7500
A25: BS_L_200 | B25: Current Liabilities | C25: 2300 | D25: 1 | E25: =E26+E27 | F25: =F26+F27 | G25: =G26+G27 | H25: 0 | I25: =IFERROR(SUMIF(Eliminations!$B$1:$B$1000,A25,Eliminations!$E$1:$E$1000),0)-IFERROR(SUMIF(Eliminations!$C$1:$C$1000,A25,Eliminations!$E$1:$E$1000),0) | J25: 0
A26: BS_L_210 | B26: Financial Liabilities (Current) | C26: 2310 | D26: 2 | E26: =E27+E28 | F26: =F27+F28 | G26: =G27+G28 | H26: 0 | I26: =IFERROR(SUMIF(Eliminations!$B$1:$B$1000,A26,Eliminations!$E$1:$E$1000),0)-IFERROR(SUMIF(Eliminations!$C$1:$C$1000,A26,Eliminations!$E$1:$E$1000),0) | J26: 0
A27: BS_L_211 | B27: - Borrowings (Current) | C27: 2311 | D27: 3 | E27: =SUMPRODUCT((LEFT(TB_Input!$A$5:$A$200,3)="310")*(TB_Input!$G$5:$G$200)) | F27: =SUMPRODUCT((LEFT(TB_Input!$A$5:$A$200,3)="310")*(TB_Input!$J$5:$J$200)) | G27: =SUMPRODUCT((LEFT(TB_Input!$A$5:$A$200,3)="310")*(TB_Input!$M$5:$M$200)) | H27: 0 | I27: =IFERROR(SUMIF(Eliminations!$B$1:$B$1000,A27,Eliminations!$E$1:$E$1000),0)-IFERROR(SUMIF(Eliminations!$C$1:$C$1000,A27,Eliminations!$E$1:$E$1000),0) | J27: 0
A28: BS_L_213 | B28: - Trade Payables | C28: 2313 | D28: 3 | E28: =SUMPRODUCT((LEFT(TB_Input!$A$5:$A$200,3)="320")*(TB_Input!$G$5:$G$200)) | F28: =SUMPRODUCT((LEFT(TB_Input!$A$5:$A$200,3)="320")*(TB_Input!$J$5:$J$200)) | G28: =SUMPRODUCT((LEFT(TB_Input!$A$5:$A$200,3)="320")*(TB_Input!$M$5:$M$200)) | H28: 0 | I28: =IFERROR(SUMIF(Eliminations!$B$1:$B$1000,A28,Eliminations!$E$1:$E$1000),0)-IFERROR(SUMIF(Eliminations!$C$1:$C$1000,A28,Eliminations!$E$1:$E$1000),0) | J28: 0

Sheet Consolidation_PL
A1: FS_Line_Code | B1: FS_Line_Name | C1: Display_Order | D1: Indent_Level | E1: E001_Jan24 | F1: E002_Jan24 | G1: E003_Jan24 | H1: Pre_Elim_Total_Jan24 | I1: Eliminations_Jan24 | J1: Post_Elim_Total_Jan24 | K1: NCI_Share_Jan24 | L1: Owners_Share_Jan24
A2: PL_I_000 | B2: TOTAL INCOME | C2: 1000 | D2: 0 | E2: =E3+E9 | F2: =F3+F9 | G2: =G3+G9 | H2: 45000 | I2: =IFERROR(SUMIF(Eliminations!$B$1:$B$1000,A2,Eliminations!$E$1:$E$1000),0)-IFERROR(SUMIF(Eliminations!$C$1:$C$1000,A2,Eliminations!$E$1:$E$1000),0) | J2: 45000 | K2: 0 | L2: =J2-K2
A3: PL_I_100 | B3: Revenue from Operations | C3: 100 | D3: 1 | E3: =E4+E5+E6+E7+E8 | F3: =F4+F5+F6+F7+F8 | G3: =G4+G5+G6+G7+G8 | H3: 45000 | I3: =IFERROR(SUMIF(Eliminations!$B$1:$B$1000,A3,Eliminations!$E$1:$E$1000),0)-IFERROR(SUMIF(Eliminations!$C$1:$C$1000,A3,Eliminations!$E$1:$E$1000),0) | J3: 45000 | K3: 0 | L3: =J3-K3
A4: PL_I_110 | B4: Sale of Power - Solar | C4: 110 | D4: 2 | E4: =SUMPRODUCT((LEFT(TB_Input!$A$5:$A$200,3)="500")*(TB_Input!$G$5:$G$200)) | F4: =SUMPRODUCT((LEFT(TB_Input!$A$5:$A$200,3)="500")*(TB_Input!$J$5:$J$200)) | G4: =SUMPRODUCT((LEFT(TB_Input!$A$5:$A$200,3)="500")*(TB_Input!$M$5:$M$200)) | H4: 15000 | I4: =IFERROR(SUMIF(Eliminations!$B$1:$B$1000,A4,Eliminations!$E$1:$E$1000),0)-IFERROR(SUMIF(Eliminations!$C$1:$C$1000,A4,Eliminations!$E$1:$E$1000),0) | J4: 15000 | K4: 0 | L4: =J4-K4
A5: PL_I_120 | B5: Sale of Power - Biogas | C5: 120 | D5: 2 | E5: =SUMPRODUCT((LEFT(TB_Input!$A$5:$A$200,3)="500")*(TB_Input!$G$5:$G$200)) | F5: =SUMPRODUCT((LEFT(TB_Input!$A$5:$A$200,3)="500")*(TB_Input!$J$5:$J$200)) | G5: =SUMPRODUCT((LEFT(TB_Input!$A$5:$A$200,3)="500")*(TB_Input!$M$5:$M$200)) | H5: 30000 | I5: =IFERROR(SUMIF(Eliminations!$B$1:$B$1000,A5,Eliminations!$E$1:$E$1000),0)-IFERROR(SUMIF(Eliminations!$C$1:$C$1000,A5,Eliminations!$E$1:$E$1000),0) | J5: 30000 | K5: 0 | L5: =J5-K5
A6: PL_I_140 | B6: EPC Revenue | C6: 140 | D6: 2 | E6: =SUMPRODUCT((LEFT(TB_Input!$A$5:$A$200,3)="510")*(TB_Input!$G$5:$G$200)) | F6: =SUMPRODUCT((LEFT(TB_Input!$A$5:$A$200,3)="510")*(TB_Input!$J$5:$J$200)) | G6: =SUMPRODUCT((LEFT(TB_Input!$A$5:$A$200,3)="510")*(TB_Input!$M$5:$M$200)) | H6: 0 | I6: =IFERROR(SUMIF(Eliminations!$B$1:$B$1000,A6,Eliminations!$E$1:$E$1000),0)-IFERROR(SUMIF(Eliminations!$C$1:$C$1000,A6,Eliminations!$E$1:$E$1000),0) | J6: 0 | K6: 0 | L6: =J6-K6
A7: PL_I_150 | B7: O&M Services Revenue | C7: 150 | D7: 2 | E7: =SUMPRODUCT((LEFT(TB_Input!$A$5:$A$200,3)="520")*(TB_Input!$G$5:$G$200)) | F7: =SUMPRODUCT((LEFT(TB_Input!$A$5:$A$200,3)="520")*(TB_Input!$J$5:$J$200)) | G7: =SUMPRODUCT((LEFT(TB_Input!$A$5:$A$200,3)="520")*(TB_Input!$M$5:$M$200)) | H7: 38900 | I7: =IFERROR(SUMIF(Eliminations!$B$1:$B$1000,A7,Eliminations!$E$1:$E$1000),0)-IFERROR(SUMIF(Eliminations!$C$1:$C$1000,A7,Eliminations!$E$1:$E$1000),0) | J7: 38900 | K7: 0 | L7: =J7-K7
A8: PL_I_170 | B8: Other Operating Revenue | C8: 170 | D8: 2 | E8: =SUMPRODUCT((LEFT(TB_Input!$A$5:$A$200,3)="530")*(TB_Input!$G$5:$G$200)) | F8: =SUMPRODUCT((LEFT(TB_Input!$A$5:$A$200,3)="530")*(TB_Input!$J$5:$J$200)) | G8: =SUMPRODUCT((LEFT(TB_Input!$A$5:$A$200,3)="530")*(TB_Input!$M$5:$M$200)) | H8: 5800 | I8: =IFERROR(SUMIF(Eliminations!$B$1:$B$1000,A8,Eliminations!$E$1:$E$1000),0)-IFERROR(SUMIF(Eliminations!$C$1:$C$1000,A8,Eliminations!$E$1:$E$1000),0) | J8: 5800 | K8: 0 | L8: =J8-K8
A9: PL_I_200 | B9: Other Income | C9: 200 | D9: 1 | E9: =SUMPRODUCT((LEFT(TB_Input!$A$5:$A$200,3)="540")*(TB_Input!$G$5:$G$200)) | F9: =SUMPRODUCT((LEFT(TB_Input!$A$5:$A$200,3)="540")*(TB_Input!$J$5:$J$200)) | G9: =SUMPRODUCT((LEFT(TB_Input!$A$5:$A$200,3)="540")*(TB_Input!$M$5:$M$200)) | H9: 3100 | I9: =IFERROR(SUMIF(Eliminations!$B$1:$B$1000,A9,Eliminations!$E$1:$E$1000),0)-IFERROR(SUMIF(Eliminations!$C$1:$C$1000,A9,Eliminations!$E$1:$E$1000),0) | J9: 3100 | K9: 0 | L9: =J9-K9
A10: PL_I_210 | B10: Interest Income | C10: 210 | D10: 2 | E10: =SUMPRODUCT((LEFT(TB_Input!$A$5:$A$200,3)="550")*(TB_Input!$G$5:$G$200)) | F10: =SUMPRODUCT((LEFT(TB_Input!$A$5:$A$200,3)="550")*(TB_Input!$J$5:$J$200)) | G10: =SUMPRODUCT((LEFT(TB_Input!$A$5:$A$200,3)="550")*(TB_Input!$M$5:$M$200)) | H10: 8500 | I10: =IFERROR(SUMIF(Eliminations!$B$1:$B$1000,A10,Eliminations!$E$1:$E$1000),0)-IFERROR(SUMIF(Eliminations!$C$1:$C$1000,A10,Eliminations!$E$1:$E$1000),0) | J10: 8500 | K10: 0 | L10: =J10-K10
A11: PL_I_220 | B11: Dividend Income | C11: 220 | D11: 2 | E11: =SUMPRODUCT((LEFT(TB_Input!$A$5:$A$200,3)="560")*(TB_Input!$G$5:$G$200)) | F11: =SUMPRODUCT((LEFT(TB_Input!$A$5:$A$200,3)="560")*(TB_Input!$J$5:$J$200)) | G11: =SUMPRODUCT((LEFT(TB_Input!$A$5:$A$200,3)="560")*(TB_Input!$M$5:$M$200)) | H11: 20000 | I11: =IFERROR(SUMIF(Eliminations!$B$1:$B$1000,A11,Eliminations!$E$1:$E$1000),0)-IFERROR(SUMIF(Eliminations!$C$1:$C$1000,A11,Eliminations!$E$1:$E$1000),0) | J11: 20000 | K11: 0 | L11: =J11-K11
A12: PL_E_000 | B12: TOTAL EXPENSES | C12: 2000 | D12: 0 | E12: =E13+E14+E15+E16+E17+E18+E19+E20 | F12: =F13+F14+F15+F16+F17+F18+F19+F20 | G12: =G13+G14+G15+G16+G17+G18+G19+G20 | H12: 1500 | I12: =IFERROR(SUMIF(Eliminations!$B$1:$B$1000,A12,Eliminations!$E$1:$E$1000),0)-IFERROR(SUMIF(Eliminations!$C$1:$C$1000,A12,Eliminations!$E$1:$E$1000),0) | J12: 1500 | K12: 0 | L12: =J12-K12
A13: PL_E_100 | B13: Cost of Power / Fuel | C13: 2100 | D13: 1 | E13: =SUMPRODUCT((LEFT(TB_Input!$A$5:$A$200,3)="600")*(TB_Input!$G$5:$G$200)) | F13: =SUMPRODUCT((LEFT(TB_Input!$A$5:$A$200,3)="600")*(TB_Input!$J$5:$J$200)) | G13: =SUMPRODUCT((LEFT(TB_Input!$A$5:$A$200,3)="600")*(TB_Input!$M$5:$M$200)) | H13: 0 | I13: =IFERROR(SUMIF(Eliminations!$B$1:$B$1000,A13,Eliminations!$E$1:$E$1000),0)-IFERROR(SUMIF(Eliminations!$C$1:$C$1000,A13,Eliminations!$E$1:$E$1000),0) | J13: 0 | K13: 0 | L13: =J13-K13
A14: PL_E_110 | B14: Cost of Materials (EPC) | C14: 2110 | D14: 1 | E14: =SUMPRODUCT((LEFT(TB_Input!$A$5:$A$200,3)="610")*(TB_Input!$G$5:$G$200)) | F14: =SUMPRODUCT((LEFT(TB_Input!$A$5:$A$200,3)="610")*(TB_Input!$J$5:$J$200)) | G14: =SUMPRODUCT((LEFT(TB_Input!$A$5:$A$200,3)="610")*(TB_Input!$M$5:$M$200)) | H14: 6100 | I14: =IFERROR(SUMIF(Eliminations!$B$1:$B$1000,A14,Eliminations!$E$1:$E$1000),0)-IFERROR(SUMIF(Eliminations!$C$1:$C$1000,A14,Eliminations!$E$1:$E$1000),0) | J14: 6100 | K14: 0 | L14: =J14-K14
A15: PL_E_120 | B15: Subcontracting Charges | C15: 2120 | D15: 1 | E15: =SUMPRODUCT((LEFT(TB_Input!$A$5:$A$200,3)="620")*(TB_Input!$G$5:$G$200)) | F15: =SUMPRODUCT((LEFT(TB_Input!$A$5:$A$200,3)="620")*(TB_Input!$J$5:$J$200)) | G15: =SUMPRODUCT((LEFT(TB_Input!$A$5:$A$200,3)="620")*(TB_Input!$M$5:$M$200)) | H15: 0 | I15: =IFERROR(SUMIF(Eliminations!$B$1:$B$1000,A15,Eliminations!$E$1:$E$1000),0)-IFERROR(SUMIF(Eliminations!$C$1:$C$1000,A15,Eliminations!$E$1:$E$1000),0) | J15: 0 | K15: 0 | L15: =J15-K15
A16: PL_E_130 | B16: Employee Benefits Expense | C16: 2130 | D16: 1 | E16: =SUMPRODUCT((LEFT(TB_Input!$A$5:$A$200,3)="630")*(TB_Input!$G$5:$G$200)) | F16: =SUMPRODUCT((LEFT(TB_Input!$A$5:$A$200,3)="630")*(TB_Input!$J$5:$J$200)) | G16: =SUMPRODUCT((LEFT(TB_Input!$A$5:$A$200,3)="630")*(TB_Input!$M$5:$M$200)) | H16: 6100 | I16: =IFERROR(SUMIF(Eliminations!$B$1:$B$1000,A16,Eliminations!$E$1:$E$1000),0)-IFERROR(SUMIF(Eliminations!$C$1:$C$1000,A16,Eliminations!$E$1:$E$1000),0) | J16: 6100 | K16: 0 | L16: =J16-K16
A17: PL_E_140 | B17: Finance Costs | C17: 2140 | D17: 1 | E17: =SUMPRODUCT((LEFT(TB_Input!$A$5:$A$200,3)="640")*(TB_Input!$G$5:$G$200)) | F17: =SUMPRODUCT((LEFT(TB_Input!$A$5:$A$200,3)="640")*(TB_Input!$J$5:$J$200)) | G17: =SUMPRODUCT((LEFT(TB_Input!$A$5:$A$200,3)="640")*(TB_Input!$M$5:$M$200)) | H17: 0 | I17: =IFERROR(SUMIF(Eliminations!$B$1:$B$1000,A17,Eliminations!$E$1:$E$1000),0)-IFERROR(SUMIF(Eliminations!$C$1:$C$1000,A17,Eliminations!$E$1:$E$1000),0) | J17: 0 | K17: 0 | L17: =J17-K17
A18: PL_E_150 | B18: Depreciation & Amortization | C18: 2150 | D18: 1 | E18: =SUMPRODUCT((LEFT(TB_Input!$A$5:$A$200,3)="650")*(TB_Input!$G$5:$G$200)) | F18: =SUMPRODUCT((LEFT(TB_Input!$A$5:$A$200,3)="650")*(TB_Input!$J$5:$J$200)) | G18: =SUMPRODUCT((LEFT(TB_Input!$A$5:$A$200,3)="650")*(TB_Input!$M$5:$M$200)) | H18: 0 | I18: =IFERROR(SUMIF(Eliminations!$B$1:$B$1000,A18,Eliminations!$E$1:$E$1000),0)-IFERROR(SUMIF(Eliminations!$C$1:$C$1000,A18,Eliminations!$E$1:$E$1000),0) | J18: 0 | K18: 0 | L18: =J18-K18
A19: PL_E_160 | B19: O&M Expenses | C19: 2160 | D19: 1 | E19: =SUMPRODUCT((LEFT(TB_Input!$A$5:$A$200,3)="660")*(TB_Input!$G$5:$G$200)) | F19: =SUMPRODUCT((LEFT(TB_Input!$A$5:$A$200,3)="660")*(TB_Input!$J$5:$J$200)) | G19: =SUMPRODUCT((LEFT(TB_Input!$A$5:$A$200,3)="660")*(TB_Input!$M$5:$M$200)) | H19: 0 | I19: =IFERROR(SUMIF(Eliminations!$B$1:$B$1000,A19,Eliminations!$E$1:$E$1000),0)-IFERROR(SUMIF(Eliminations!$C$1:$C$1000,A19,Eliminations!$E$1:$E$1000),0) | J19: 0 | K19: 0 | L19: =J19-K19
A20: PL_E_170 | B20: Other Expenses | C20: 2170 | D20: 1 | E20: =SUMPRODUCT((LEFT(TB_Input!$A$5:$A$200,3)="670")*(TB_Input!$G$5:$G$200)) | F20: =SUMPRODUCT((LEFT(TB_Input!$A$5:$A$200,3)="670")*(TB_Input!$J$5:$J$200)) | G20: =SUMPRODUCT((LEFT(TB_Input!$A$5:$A$200,3)="670")*(TB_Input!$M$5:$M$200)) | H20: 0 | I20: =IFERROR(SUMIF(Eliminations!$B$1:$B$1000,A20,Eliminations!$E$1:$E$1000),0)-IFERROR(SUMIF(Eliminations!$C$1:$C$1000,A20,Eliminations!$E$1:$E$1000),0) | J20: 0 | K20: 0 | L20: =J20-K20
A21: PL_I_900 | B21: EBITDA | C21: 900 | D21: 3 | E21: =E3-E13 | F21: =F3-F13 | G21: =G3-G13 | H21: 0 | I21: 0 | J21: 0 | K21: =J21-IFERROR(G21*0.4,0)
A22: PL_R_100 | B22: Profit before Tax | C22: 3100 | D22: 1 | E22: =E2-E12 | F22: =F2-F12 | G22: =G2-G12 | H22: 0 | I22: =IFERROR(SUMIF(Eliminations!$B$1:$B$1000,A21,Eliminations!$E$1:$E$1000),0)-IFERROR(SUMIF(Eliminations!$C$1:$C$1000,A21,Eliminations!$E$1:$E$1000),0) | J22: 0 | K22: =G21*0.40 | L22: =L2-L12
A23: PL_R_110 | B23: Tax Expense - Current | C23: 3110 | D23: 2 | E23: =SUMPRODUCT((LEFT(TB_Input!$A$5:$A$200,3)="700")*(TB_Input!$G$5:$G$200)) | F23: =SUMPRODUCT((LEFT(TB_Input!$A$5:$A$200,3)="700")*(TB_Input!$J$5:$J$200)) | G23: =SUMPRODUCT((LEFT(TB_Input!$A$5:$A$200,3)="700")*(TB_Input!$M$5:$M$200)) | H23: 0 | I23: =IFERROR(SUMIF(Eliminations!$B$1:$B$1000,A22,Eliminations!$E$1:$E$1000),0)-IFERROR(SUMIF(Eliminations!$C$1:$C$1000,A22,Eliminations!$E$1:$E$1000),0) | J23: 0 | K23: 0 | L23: =J22-K22
A24: PL_R_120 | B24: Tax Expense - Deferred | C24: 3120 | D24: 2 | E24: =SUMPRODUCT((LEFT(TB_Input!$A$5:$A$200,3)="701")*(TB_Input!$G$5:$G$200)) | F24: =SUMPRODUCT((LEFT(TB_Input!$A$5:$A$200,3)="701")*(TB_Input!$J$5:$J$200)) | G24: =SUMPRODUCT((LEFT(TB_Input!$A$5:$A$200,3)="701")*(TB_Input!$M$5:$M$200)) | H24: 0 | I24: =IFERROR(SUMIF(Eliminations!$B$1:$B$1000,A23,Eliminations!$E$1:$E$1000),0)-IFERROR(SUMIF(Eliminations!$C$1:$C$1000,A23,Eliminations!$E$1:$E$1000),0) | J24: 0 | K24: 0 | L24: =J23-K23
A25: PL_R_200 | B25: Profit for the Year | C25: 3200 | D25: 1 | E25: =E21-E22-E23 | F25: =F21-F22-F23 | G25: =G21-G22-G23 | H25: 0 | I25: =IFERROR(SUMIF(Eliminations!$B$1:$B$1000,A24,Eliminations!$E$1:$E$1000),0)-IFERROR(SUMIF(Eliminations!$C$1:$C$1000,A24,Eliminations!$E$1:$E$1000),0) | J25: 0 | K25: =G24*0.40 | L25: =L21-L22-L23
A26: PL_R_300 | B26: Attributable to Owners | C26: 3300 | D26: 2 | E26: 0 | F26: 0 | G26: 0 | H26: 0 | I26: =IFERROR(SUMIF(Eliminations!$B$1:$B$1000,A25,Eliminations!$E$1:$E$1000),0)-IFERROR(SUMIF(Eliminations!$C$1:$C$1000,A25,Eliminations!$E$1:$E$1000),0) | J26: 0 | K26: 0 | L26: =J25-K25
A27: PL_R_310 | B27: Attributable to NCI | C27: 3310 | D27: 2 | E27: 0 | F27: 0 | G27: 0 | H27: 0 | I27: =IFERROR(SUMIF(Eliminations!$B$1:$B$1000,A26,Eliminations!$E$1:$E$1000),0)-IFERROR(SUMIF(Eliminations!$C$1:$C$1000,A26,Eliminations!$E$1:$E$1000),0) | J27: 0 | K27: 0 | L27: =J26-K26

Sheet Consolidation_CF
A1: CF_Line_Code | B1: CF_Line_Name | C1: Amount_Jan24
A2: CF_O_000 | B2: A. CASH FLOW FROM OPERATING ACTIVITIES
A3: CF_O_010 | B3: Profit before Tax | C3: 6100
A4: CF_O_020 | B4: Adjustments:
A5: CF_O_021 | B5: Depreciation & Amortization | C5: =IFERROR(INDEX(Consolidation_PL!$J$1:$J$100,MATCH("PL_E_150",Consolidation_PL!$A$1:$A$100,0)),0)
A6: CF_O_022 | B6: Finance Costs | C6: =IFERROR(INDEX(Consolidation_PL!$J$1:$J$100,MATCH("PL_E_140",Consolidation_PL!$A$1:$A$100,0)),0)
A7: CF_O_023 | B7: Interest Income | C7: =-1*IFERROR(INDEX(Consolidation_PL!$J$1:$J$100,MATCH("PL_I_210",Consolidation_PL!$A$1:$A$100,0)),0)
A8: CF_O_030 | B8: Operating Profit before WC changes | C8: =SUM(C1:C7)
A9: CF_O_040 | B9: Working Capital changes:
A10: CF_O_041 | B10: (Increase)/Decrease in Receivables | C10: =-1*(IFERROR(INDEX(Consolidation_BS!$J$1:$J$100,MATCH("BS_A_221",Consolidation_BS!$A$1:$A$100,0)),0)-0)
A11: CF_O_042 | B11: Increase/(Decrease) in Payables | C11: =IFERROR(INDEX(Consolidation_BS!$J$1:$J$100,MATCH("BS_L_213",Consolidation_BS!$A$1:$A$100,0)),0)-0
A12: CF_O_050 | B12: Cash Generated from Operations | C12: =C9+C10+C11
A13: CF_O_060 | B13: Income Tax Paid | C13: =-1*IFERROR(INDEX(Consolidation_PL!$J$1:$J$100,MATCH("PL_R_110",Consolidation_PL!$A$1:$A$100,0)),0)
A14: CF_O_100 | B14: Net Cash from Operating Activities (A) | C14: =C2+SUM(C3:C13)
A15: CF_I_000 | B15: B. CASH FLOW FROM INVESTING ACTIVITIES
A16: CF_I_010 | B16: Purchase of PPE | C16: =-1*(IFERROR(INDEX(Consolidation_BS!$J$1:$J$100,MATCH("BS_A_110",Consolidation_BS!$A$1:$A$100,0)),0)-0)
A17: CF_I_020 | B17: Interest Received | C17: =IFERROR(INDEX(Consolidation_PL!$J$1:$J$100,MATCH("PL_I_210",Consolidation_PL!$A$1:$A$100,0)),0)
A18: CF_I_100 | B18: Net Cash from Investing Activities (B) | C18: =SUM(C16:C17)
A19: CF_F_000 | B19: C. CASH FLOW FROM FINANCING ACTIVITIES
A20: CF_F_010 | B20: Proceeds from Borrowings | C20: =IFERROR(INDEX(Consolidation_BS!$J$1:$J$100,MATCH("BS_L_111",Consolidation_BS!$A$1:$A$100,0)),0)
A21: CF_F_020 | B21: Interest Paid | C21: =-1*IFERROR(INDEX(Consolidation_PL!$J$1:$J$100,MATCH("PL_E_140",Consolidation_PL!$A$1:$A$100,0)),0)
A22: CF_F_100 | B22: Net Cash from Financing Activities (C) | C22: =SUM(C20:C21)
A23: CF_S_000 | B23: SUMMARY
A24: CF_S_010 | B24: Net Increase/(Decrease) in Cash (A+B+C) | C24: =IFERROR(INDEX(C:C,MATCH("CF_O_100",A:A,0)),0)+IFERROR(INDEX(C:C,MATCH("CF_I_100",A:A,0)),0)+IFERROR(INDEX(C:C,MATCH("CF_F_100",A:A,0)),0)
A25: CF_S_020 | B25: Cash at Beginning of Period | C25: 0
A26: CF_S_030 | B26: Cash at End of Period | C26: =IFERROR(INDEX(Consolidation_BS!$J$1:$J$100,MATCH("BS_A_222",Consolidation_BS!$A$1:$A$100,0)),0)

Sheet Eliminations
A1: Elimination_Type | B1: FS_Line_Code_Dr | C1: FS_Line_Code_Cr | D1: Description | E1: Amount_Jan24 | F1: Formula_Notes
A2: EPC_Revenue_Elim | B2: PL_I_140 | D2: Eliminate EPC revenue from Parent to SPV | E2: =IC_Transactions!F2 | F2: IC001 - EPC Revenue elimination
A3: Profit_in_CWIP | B3: BS_A_120 | D3: Eliminate unrealized profit in CWIP | E3: =-IC_Transactions!H2 | F3: IC001 - 10% profit margin elimination
A4: IC_Loan_Elim_Asset | C4: BS_A_153 | D4: Eliminate IC loan receivable | E4: =IC_Transactions!F3 | F4: IC002 - Loan asset elimination
A5: IC_Loan_Elim_Liab | B5: BS_L_211 | D5: Eliminate IC loan payable | E5: =IC_Transactions!F3 | F5: IC002 - Loan liability elimination
A6: IC_Interest_Elim_Inc | C6: PL_I_210 | D6: Eliminate IC interest income | E6: =IC_Transactions!F4 | F6: IC003 - Interest income elimination
A7: IC_Interest_Elim_Exp | B7: PL_E_140 | D7: Eliminate IC interest expense | E7: =IC_Transactions!F4 | F7: IC003 - Interest expense elimination

Sheet Output_BS
A1: PARENT RENEWABLE LTD
A2: CONSOLIDATED BALANCE SHEET
A3: As at 31st March 2024
A4: (All amounts in ₹ Lacs unless otherwise stated)
B5: =Consolidation_BS!I5 | C5: 0
A6: Particulars | B6: Note | C6: FY2024 | D6: FY2023 | E6: Variance | F6: Variance %
A7: ASSETS | B7: =Consolidation_BS!I7 | C7: 137500
A8: Non-Current Assets | B8: =Consolidation_BS!I8 | C8: 119500
A9: Property, Plant & Equipment | B9: 1 | C9: 77500 | D9: 0
A10: Capital Work-in-Progress | B10: 2 | C10: 42000 | D10: 0
A11: Investments in JV/Associates | B11: 3 | C11: 0 | D11: 0
A12: Total Non-Current Assets | B12: =Consolidation_BS!I12 | C12: 0 | E12: =C12-D12 | F12: =IFERROR(E12/D12,0)
A13: Current Assets | B13: =Consolidation_BS!I13 | C13: 0
A14: Trade Receivables | B14: 4 | C14: 0 | D14: 0
A15: Cash and Cash Equivalents | B15: 5 | C15: 0 | D15: 0
A16: Total Current Assets | B16: =Consolidation_BS!I16 | C16: 20000 | E16: =C16-D16 | F16: =IFERROR(E16/D16,0)
A17: TOTAL ASSETS | B17: =Consolidation_BS!I17 | C17: 18000 | E17: =C17-D17 | F17: =IFERROR(E17/D17,0)
B18: =Consolidation_BS!I18 | C18: 0
A19: EQUITY AND LIABILITIES | B19: =Consolidation_BS!I19 | C19: 18000
A20: Equity | B20: =Consolidation_BS!I20 | C20: 0
A21: Equity Share Capital | B21: 6 | C21: 0 | D21: 0
A22: Other Equity | B22: 7 | C22: 45000 | D22: 0
A23: Non-Controlling Interests | B23: 8 | C23: 3000 | D23: 0
A24: Total Equity | B24: =Consolidation_BS!I24 | C24: 0 | E24: =C24-D24 | F24: =IFERROR(E24/D24,0)
A25: Non-Current Liabilities | B25: =Consolidation_BS!I25 | C25: 0
A26: Borrowings (Non-Current) | B26: 9 | C26: 45000 | D26: 0
A27: Total Non-Current Liabilities | B27: =Consolidation_BS!I27 | C27: 0 | E27: =C27-D27 | F27: =IFERROR(E27/D27,0)
A28: Current Liabilities | B28: =Consolidation_BS!I28 | C28: 0
A29: Borrowings (Current) | B29: 10 | C29: 7500 | D29: 0
A30: Trade Payables | B30: 11 | C30: 0 | D30: 0
A31: Total Current Liabilities | C31: 0 | E31: =C31-D31 | F31: =IFERROR(E31/D31,0)
A32: TOTAL EQUITY AND LIABILITIES | C32: 0 | E32: =C32-D32 | F32: =IFERROR(E32/D32,0)
C33: 0
A34: NOTE: This output should link to:
A35: =Consolidation_BS!Post_Elim_Total[Selected_Period]

Sheet Output_PL
A1: PARENT RENEWABLE LTD
A2: CONSOLIDATED STATEMENT OF PROFIT AND LOSS
A3: For the year ended 31st March 2024
A4: (All amounts in ₹ Lacs unless otherwise stated)
B5: =Consolidation_PL!K5 | C5: 0
A6: Particulars | B6: Note | C6: FY2024 | D6: FY2023 | E6: Variance | F6: Variance %
A7: INCOME | B7: =Consolidation_PL!K7 | C7: 45000
A8: Revenue from Operations | B8: =Consolidation_PL!K8 | C8: 45000
A9: Sale of Power - Solar | B9: 12 | C9: 15000 | D9: 0
A10: Sale of Power - Biogas | B10: 13 | C10: 30000 | D10: 0
A11: EPC Revenue | B11: 14 | C11: 0 | D11: 0
A12: Total Revenue from Operations | B12: =Consolidation_PL!K12 | C12: 38900 | E12: =C12-D12 | F12: =IFERROR(E12/D12,0)
A13: Other Income | B13: 15 | C13: 5800 | D13: 0
A14: Total Income | B14: =Consolidation_PL!K14 | C14: 3100 | E14: =C14-D14 | F14: =IFERROR(E14/D14,0)
B15: =Consolidation_PL!K15 | C15: 8500
A16: EXPENSES | B16: =Consolidation_PL!K16 | C16: 20000
A17: Cost of Materials (EPC) | B17: 16 | C17: 1500 | D17: 0
A18: Employee Benefits | B18: 17 | C18: 0 | D18: 0
A19: Finance Costs | B19: 18 | C19: 6100 | D19: 0
A20: Depreciation & Amortization | B20: 19 | C20: 0 | D20: 0
A21: Other Expenses | B21: 20 | C21: 6100 | D21: 0
A22: Total Expenses | B22: =Consolidation_PL!K22 | C22: 0 | E22: =C22-D22 | F22: =IFERROR(E22/D22,0)
A23: EBITDA | B23: =Consolidation_PL!K21 | C23: 0
B24: =Consolidation_PL!K23 | C24: 0
A25: Profit before Tax | B25: =Consolidation_PL!K24 | C25: 0 | D25: 0
A26: Tax Expense | B26: 21 | C26: 0 | D26: 0
A27: Profit for the Year | B27: =Consolidation_PL!K26 | C27: 0 | D27: 0
C28: 0
A29: Attributable to: | C29: 0
A30: Owners of the Company | C30: 0 | D30: 0
A31: Non-Controlling Interests | C31: 0 | D31: 0
A32: Profit for the Year | C32: 0 | D32: 0
A34: NOTE: This output should link to:
A35: =Consolidation_PL!Post_Elim_Total[Selected_Period]

Sheet Output_CF
A1: PARENT RENEWABLE LTD
A2: CONSOLIDATED STATEMENT OF CASH FLOWS
A3: For the year ended 31st March 2024 (Indirect Method)
A4: (All amounts in ₹ Lacs unless otherwise stated)
B5: =Consolidation_CF!H5 | C5: 0
A6: Particulars | B6: FY2024 | C6: FY2023
A7: A. CASH FLOW FROM OPERATING ACTIVITIES | B7: =Consolidation_CF!H7 | C7: 0
A8: Profit before Tax | B8: =Consolidation_CF!H8 | C8: 0
A9: Adjustments: | B9: =Consolidation_CF!H9 | C9: 0
A10: Depreciation & Amortization | B10: =Consolidation_CF!H10 | C10: 0
A11: Finance Costs | B11: =Consolidation_CF!H11 | C11: 0
A12: Interest Income | B12: =Consolidation_CF!H12 | C12: 0
A13: Operating Profit before WC changes | B13: =Consolidation_CF!H13 | C13: 0
A14: Working Capital changes: | B14: =Consolidation_CF!H14 | C14: 0
A15: (Increase)/Decrease in Receivables | B15: =Consolidation_CF!H15 | C15: 0
A16: Increase/(Decrease) in Payables | B16: =Consolidation_CF!H16 | C16: 0
A17: Cash Generated from Operations | B17: =Consolidation_CF!H17 | C17: 0
A18: Income Tax Paid | B18: =Consolidation_CF!H18 | C18: 0
A19: Net Cash from Operating Activities (A) | B19: =Consolidation_CF!H19 | C19: 0
B20: =Consolidation_CF!H20 | C20: 0
A21: B. CASH FLOW FROM INVESTING ACTIVITIES | B21: =Consolidation_CF!H21 | C21: 0
A22: Purchase of PPE | B22: =Consolidation_CF!H22 | C22: 0
A23: Interest Received | B23: =Consolidation_CF!H23 | C23: 0
A24: Net Cash from Investing Activities (B) | B24: =Consolidation_CF!H24 | C24: 0
B25: =Consolidation_CF!H25 | C25: 0
A26: C. CASH FLOW FROM FINANCING ACTIVITIES | B26: =Consolidation_CF!H26 | C26: 0
A27: Proceeds from Borrowings
A28: Interest Paid
A29: Net Cash from Financing Activities (C)
A31: Net Increase/(Decrease) in Cash (A+B+C)
A32: Cash at Beginning of Period
A33: Cash at End of Period
A35: NOTE: This output should link to:
A36: =Consolidation_CF!Post_Elim_Total[Selected_Period]

Sheet Output_Segment

Sheet Period_Control
A1: Parameter | B1: Value | C1: Description
A2: Current_Period | B2: Jan-2024 | C2: Selected reporting period
A3: Comparison_Period | B3: Dec-2023 | C3: Previous period for comparison
A4: Display_Mode | B4: Monthly | C4: Monthly/Quarterly/Annual
A5: Reporting_Currency | B5: INR | C5: Currency for display
A6: FY_Start_Month | B6: April | C6: Financial year start month
A7: Rounding | B7: Lacs | C7: Display in Cr/Lacs/thousands

Sheet Validation
A1: Check # | B1: Check Description | C1: Expected | D1: Actual | E1: Status | F1: Variance
A2: V01 | B2: BS Balances (Assets = Liab + Equity) | C2: 0 | D2: =IFERROR(INDEX(Consolidation_BS!$J$1:$J$100,MATCH("BS_A_000",Consolidation_BS!$A$1:$A$100,0)),0)-IFERROR(INDEX(Consolidation_BS!$J$1:$J$100,MATCH("BS_E_000",Consolidation_BS!$A$1:$A$100,0)),0) | E2: =IF(ABS(D2)<0.01,"PASS","FAIL") | F2: TOTAL FAILS: | G2: =COUNTIF($E$2:$E$20,"FAIL")
A3: V02 | B3: IC Receivables = IC Payables | C3: 0 | D3: =IFERROR(SUMIF(IC_Transactions!$B$1:$B$100,"Loan_Given",IC_Transactions!$F$1:$F$100),0) | E3: =IF(ABS(D3-IFERROR(INDEX(Consolidation_BS!$J$1:$J$100,MATCH("BS_A_153",Consolidation_BS!$A$1:$A$100,0)),0))<0.01,"PASS","FAIL") | F3: =D3
A4: V03 | B4: TB Debit = Credit (E001, Jan-24) | C4: 0 | D4: =IFERROR(TB_Input!E23-TB_Input!F23,0) | E4: =IF(ABS(D4)<0.01,"PASS","FAIL") | F4: =D4
A5: V04 | B5: TB Debit = Credit (E002, Jan-24) | C5: 0 | D5: =IFERROR(TB_Input!H23-TB_Input!I23,0) | E5: =IF(ABS(D5)<0.01,"PASS","FAIL") | F5: =D5
A6: V05 | B6: Cash Flow Reconciliation | C6: 0 | D6: =IFERROR(INDEX(Consolidation_CF!$C$1:$C$100,MATCH("CF_S_030",Consolidation_CF!$A$1:$A$100,0)),0) | E6: =IF(ABS(D6-IFERROR(INDEX(Consolidation_BS!$J$1:$J$100,MATCH("BS_A_222",Consolidation_BS!$A$1:$A$100,0)),0))<1,"PASS","FAIL") | F6: =D6
A7: V06 | B7: NCI Calculation Check | C7: Match | D7: =IFERROR(INDEX(Consolidation_PL!$K$1:$K$100,MATCH("PL_R_200",Consolidation_PL!$A$1:$A$100,0)),0) | E7: =IF(D7>=0,"PASS","CHECK") | F7: =D7
A8: V07 | B8: Ownership % Valid (0-100%) | C8: All Valid | D8: =COUNTIFS(Entity_Master!$E$5:$E$20,"<0")+COUNTIFS(Entity_Master!$E$5:$E$20,">100") | E8: =IF(D8=0,"PASS","FAIL") | F8: 0
A9: V08 | B9: No Circular Ownership | C9: None | D9: =COUNTA(Entity_Master!$A$5:$A$20) | E9: =IF(D9>0,"PASS","CHECK") | F9: 0
A10: V09 | B10: Elimination Impact = Zero | C10: 0 | D10: =IFERROR(SUM(Eliminations!$C$5:$F$20),0) | E10: =IF(ABS(D10)<0.01,"PASS","CHECK") | F10: 0
A11: V10 | B11: Entity Master Integrity | C11: Valid | D11: =COUNTBLANK(Entity_Master!$A$5:$A$20)-COUNTBLANK(Entity_Master!$B$5:$B$20) | E11: =IF(D11=0,"PASS","CHECK") | F11: 0
A12: V11 | B12: Unmapped Accounts Detection | C12: 0 | D12: =COUNTIF(TB_Input!$A$5:TB_Input!$A$1000,"???*")-COUNTA(Mapping_BS!$G$1:$G$100)-COUNTA(Mapping_PL!$G$1:$G$100) | E12: =IF(D12=0,"PASS","CHECK") | F12: =D12
A13: V12 | B13: All TB Entities exist in Entity_Master | C13: All Valid | D13: =COUNTIF(Entity_Master!$A$1:$A$100,"E00?") | E13: =IF(D13>=3,"PASS","CHECK") | F13: =D13
A14: V13 | B14: All IC Transactions have Eliminations | C14: Match | D14: =COUNTA(IC_Transactions!$A$1:$A$100)-1 | E14: =IF(D14<=COUNTA(Eliminations!$A$1:$A$100)-1,"PASS","CHECK") | F14: =D14
A15: V14 | B15: No Duplicate Entity_IDs | C15: None | D15: =COUNTA(Entity_Master!$A$1:$A$100)-1 | E15: =IF(D15=SUMPRODUCT(1/COUNTIF(Entity_Master!$A$2:Entity_Master!$A$100,Entity_Master!$A$2:Entity_Master!$A$100))+1,"PASS","FAIL") | F15: 0
A16: V15 | B16: All Ownership % between 0-100% | C16: Valid | D16: =COUNTIFS(Entity_Master!$E$1:$E$100,">=0",Entity_Master!$E$1:$E$100,"<=1") | E16: =IF(D16>=COUNTA(Entity_Master!$E$1:$E$100)-1,"PASS","FAIL") | F16: =D16
A30: Total Failed Checks | C30: =COUNTIF(C5:C25,"FAIL")

Sheet Instructions
A1: RENEWABLE ENERGY CONSOLIDATION MODEL - USER GUIDE
A4: 1. MODEL OVERVIEW
A5: This Excel model provides complete financial consolidation for renewable energy companies
A6: with hybrid EPC + IPP business models.
A8: 2. GETTING STARTED
A9: - Start with the Dashboard sheet for navigation
A10: - Review Entity_Master and Asset_Master to understand the structure
A11: - Input monthly trial balances in TB_Input sheet
A12: - Track intercompany transactions in IC_Transactions sheet
A14: 3. MASTER DATA SETUP
A15: Entity_Master: Add all entities (Parent, SPVs, JVs, Associates)
